<?xml version="1.0"?>
<robot name="rover" xmlns:xacro="http://www.ros.org/wiki/xacro" >

   
  <xacro:property name="wheel_radius" value="0.04"/>
  <xacro:property name="wheel_length" value="0.05"/>
  


  <xacro:macro name="wheel" params="name">
    <link name="${name}">
      <visual>
        <geometry>
          <cylinder radius="${wheel_radius}" length="${wheel_length}" />
        </geometry>
        <material name="Black" />
      </visual>
    </link> 
  </xacro:macro>

  <xacro:macro name="chasis_link" params="name size colour">
    <link name="${name}">
      <visual>
        <geometry>
          <box size="${size}"/>
        </geometry>
        <material name="${colour}"/>
      </visual>
    </link>
  </xacro:macro>

  <xacro:macro name="static_joint" params="name parent child" >
    <joint name="${name}" type="fixed">
      <parent link="${parent}"/>
      <child link="${child}"/>
      <origin xyz="0 0 0" rpy="0 0 0"/>
    </joint>
  </xacro:macro>

  <xacro:macro name="wheel_joint" params="name parent child xyz ">
    <joint name="${name}" type="continuous">
      <axis xyz="0 0 1" />
      <parent link="${parent}" />
      <child link="${child}" />
      <origin xyz="${xyz}" rpy="1.570796 0 0"/>
    </joint>
  </xacro:macro>

</robot>