<?xml version="1.0"?>
<robot name="rover" xmlns:xacro="http://www.ros.org/wiki/xacro" >

  <xacro:property name="wheel_radius" value="0.04"/>
  <xacro:property name="wheel_length" value="0.05"/>

  <xacro:macro name="wheel" params="name">
    <link name="${name}">
      <visual>
        <geometry>
          <cylinder radius="${wheel_radius}" length="${wheel_length}" />
        </geometry>
        <material name="Black" />
      </visual>
    </link> 
  </xacro:macro>

  <xacro:macro name="chasis_link" params="name size colour">
    <link name="${name}">
      <inertial>
        <mass value="0.25"/>
        <inertia ixx="0.000486" ixy="0.0" ixz="0.0" iyy="0.000486" iyz="0.0" izz="0.000729"/>
      </inertial>  
      <visual>
        <geometry>
          <box size="${size}"/>
        </geometry>
        <material name="${colour}"/>
      </visual>
      <collision>
        <origin rpy="0 0 0" xyz="0 0 0"/>
        <geometry>
          <cylinder radius="0.09" length="0.09"/>
        </geometry>
      </collision>
      <gazebo reference="front_roll_link">
        <material>Gazebo/Orange</material>
      </gazebo>
   </link>
  </xacro:macro>

  <xacro:macro name="static_joint" params="name parent child" >
    <joint name="${name}" type="fixed">
      <parent link="${parent}"/>
      <child link="${child}"/>
      <origin xyz="0 0 0" rpy="0 0 0"/>
    </joint>
  </xacro:macro>

  <xacro:macro name="wheel_joint" params="name parent child xyz ">
    <joint name="${name}" type="continuous">
      <axis xyz="0 0 1" />
      <parent link="${parent}" />
      <child link="${child}" />
      <origin xyz="${xyz}" rpy="1.570796 0 0"/>
    </joint>
  </xacro:macro>

</robot>
