<?xml version="1.0" ?>
<!-- =================================================================================== -->
<!-- |    This document was autogenerated by xacro from src/rover_description/urdf/rover.urdf.xml | -->
<!-- |    EDITING THIS FILE BY HAND IS NOT RECOMMENDED                                 | -->
<!-- =================================================================================== -->
<robot name="rover">
  <material name="Black">
    <color rgba="0.1 0.1 0.1 1.0"/>
  </material>
  <material name="Green">
    <color rgba="0.0 0.8 0.0 1.0"/>
  </material>
  <material name="aluminum">
    <color rgba="0.5 0.5 0.5 1.0"/>
  </material>
  <material name="DarkGrey">
    <color rgba="0.3 0.3 0.3 1.0"/>
  </material>
  <material name="GunMetalGrey">
    <color rgba="0.46 0.5 0.56 1.0"/>
  </material>
  <material name="Gold">
    <color rgba="1 1 0.752941176470588 1"/>
  </material>
  <material name="zedm_mat">
    <color rgba="0 0 0 0.9"/>
  </material>
  <!-- pi, fisheye -->
  <!-- rover definition -->
  <link name="base_link"/>
  <link name="body">
    <visual>
      <geometry>
        <box size="0.6 0.3 0.1"/>
      </geometry>
      <material name="Black"/>
    </visual>
  </link>
  <joint name="base_joint" type="fixed">
    <parent link="base_link"/>
    <child link="body"/>
    <origin rpy="0 0 0" xyz="0 0 0"/>
  </joint>
  <link name="right_wheel_frontside">
    <visual>
      <geometry>
        <cylinder length="0.05" radius="0.04"/>
      </geometry>
      <material name="Black"/>
    </visual>
  </link>
  <joint name="base_link_right_wheel_frontside" type="continuous">
    <axis xyz="0 0 1"/>
    <parent link="base_link"/>
    <child link="right_wheel_frontside"/>
    <origin rpy="1.570796 0 0" xyz="0.2 -0.2 -0.05"/>
  </joint>
  <link name="right_wheel_backside">
    <visual>
      <geometry>
        <cylinder length="0.05" radius="0.04"/>
      </geometry>
      <material name="Black"/>
    </visual>
  </link>
  <joint name="base_link_right_wheel_backside" type="continuous">
    <axis xyz="0 0 1"/>
    <parent link="base_link"/>
    <child link="right_wheel_backside"/>
    <origin rpy="1.570796 0 0" xyz="-0.2 -0.2 -0.05"/>
  </joint>
  <link name="left_wheel_frontside">
    <visual>
      <geometry>
        <cylinder length="0.05" radius="0.04"/>
      </geometry>
      <material name="Black"/>
    </visual>
  </link>
  <joint name="base_link_left_wheel_frontside" type="continuous">
    <axis xyz="0 0 1"/>
    <parent link="base_link"/>
    <child link="left_wheel_frontside"/>
    <origin rpy="1.570796 0 0" xyz="0.2 0.2 -0.05"/>
  </joint>
  <link name="left_wheel_backside">
    <visual>
      <geometry>
        <cylinder length="0.05" radius="0.04"/>
      </geometry>
      <material name="Black"/>
    </visual>
  </link>
  <joint name="base_link_left_wheel_backside" type="continuous">
    <axis xyz="0 0 1"/>
    <parent link="base_link"/>
    <child link="left_wheel_backside"/>
    <origin rpy="1.570796 0 0" xyz="-0.2 0.2 -0.05"/>
  </joint>
</robot>
